Workbook

Sheet Resultados
A1: Nombre completo ✎ | H1: Encabezado en CSV | I1: Hora | J1: ="Real · "&$B$1 | K1: ="Reconstruida · "&$B$1
A2: Código de alumno ✎ | H2: =IFERROR(MATCH("hora",CSV!$A:$A,0),"") | I2: =IF($H$2="",NA(),IF(INDEX(CSV!$A:$A,$H$2+1)="",NA(),INDEX(CSV!$A:$A,$H$2+1)*1)) | J2: =IF($H$2="",NA(),IF(INDEX(CSV!$B:$B,$H$2+1)="",NA(),INDEX(CSV!$B:$B,$H$2+1)*1)) | K2: =IF($H$2="",NA(),IF(INDEX(CSV!$D:$D,$H$2+1)="",NA(),INDEX(CSV!$D:$D,$H$2+1)*1))
A3: Código en el CSV | B3: =IFERROR(VLOOKUP("codigo",CSV!$A:$B,2,FALSE),"") | I3: =IF($H$2="",NA(),IF(INDEX(CSV!$A:$A,$H$2+2)="",NA(),INDEX(CSV!$A:$A,$H$2+2)*1)) | J3: =IF($H$2="",NA(),IF(INDEX(CSV!$B:$B,$H$2+2)="",NA(),INDEX(CSV!$B:$B,$H$2+2)*1)) | K3: =IF($H$2="",NA(),IF(INDEX(CSV!$D:$D,$H$2+2)="",NA(),INDEX(CSV!$D:$D,$H$2+2)*1))
A4: Verificación | B4: =IF(B3="","Importa tu CSV",IF(B2="","Escribe tu código",IF(TRIM(B3&"")=TRIM(B2&""),"OK","NO COINCIDE"))) | I4: =IF($H$2="",NA(),IF(INDEX(CSV!$A:$A,$H$2+3)="",NA(),INDEX(CSV!$A:$A,$H$2+3)*1)) | J4: =IF($H$2="",NA(),IF(INDEX(CSV!$B:$B,$H$2+3)="",NA(),INDEX(CSV!$B:$B,$H$2+3)*1)) | K4: =IF($H$2="",NA(),IF(INDEX(CSV!$D:$D,$H$2+3)="",NA(),INDEX(CSV!$D:$D,$H$2+3)*1))
A5: Huella del cuaderno | B5: =IFERROR(VLOOKUP("huella",CSV!$A:$B,2,FALSE),"") | I5: =IF($H$2="",NA(),IF(INDEX(CSV!$A:$A,$H$2+4)="",NA(),INDEX(CSV!$A:$A,$H$2+4)*1)) | J5: =IF($H$2="",NA(),IF(INDEX(CSV!$B:$B,$H$2+4)="",NA(),INDEX(CSV!$B:$B,$H$2+4)*1)) | K5: =IF($H$2="",NA(),IF(INDEX(CSV!$D:$D,$H$2+4)="",NA(),INDEX(CSV!$D:$D,$H$2+4)*1))
A6: Sesión | B6: =IFERROR(VLOOKUP("sesion",CSV!$A:$B,2,FALSE),"") | I6: =IF($H$2="",NA(),IF(INDEX(CSV!$A:$A,$H$2+5)="",NA(),INDEX(CSV!$A:$A,$H$2+5)*1)) | J6: =IF($H$2="",NA(),IF(INDEX(CSV!$B:$B,$H$2+5)="",NA(),INDEX(CSV!$B:$B,$H$2+5)*1)) | K6: =IF($H$2="",NA(),IF(INDEX(CSV!$D:$D,$H$2+5)="",NA(),INDEX(CSV!$D:$D,$H$2+5)*1))
A7: Fuente de los datos | B7: =IFERROR(VLOOKUP("fuente",CSV!$A:$B,2,FALSE),"") | I7: =IF($H$2="",NA(),IF(INDEX(CSV!$A:$A,$H$2+6)="",NA(),INDEX(CSV!$A:$A,$H$2+6)*1)) | J7: =IF($H$2="",NA(),IF(INDEX(CSV!$B:$B,$H$2+6)="",NA(),INDEX(CSV!$B:$B,$H$2+6)*1)) | K7: =IF($H$2="",NA(),IF(INDEX(CSV!$D:$D,$H$2+6)="",NA(),INDEX(CSV!$D:$D,$H$2+6)*1))
A8: Semana | B8: =IFERROR(VLOOKUP("semana",CSV!$A:$B,2,FALSE),"") | I8: =IF($H$2="",NA(),IF(INDEX(CSV!$A:$A,$H$2+7)="",NA(),INDEX(CSV!$A:$A,$H$2+7)*1)) | J8: =IF($H$2="",NA(),IF(INDEX(CSV!$B:$B,$H$2+7)="",NA(),INDEX(CSV!$B:$B,$H$2+7)*1)) | K8: =IF($H$2="",NA(),IF(INDEX(CSV!$D:$D,$H$2+7)="",NA(),INDEX(CSV!$D:$D,$H$2+7)*1))
A9: Tu resistencia fija (Ω) | B9: =IFERROR(VLOOKUP("rf_ohm",CSV!$A:$B,2,FALSE),"") | I9: =IF($H$2="",NA(),IF(INDEX(CSV!$A:$A,$H$2+8)="",NA(),INDEX(CSV!$A:$A,$H$2+8)*1)) | J9: =IF($H$2="",NA(),IF(INDEX(CSV!$B:$B,$H$2+8)="",NA(),INDEX(CSV!$B:$B,$H$2+8)*1)) | K9: =IF($H$2="",NA(),IF(INDEX(CSV!$D:$D,$H$2+8)="",NA(),INDEX(CSV!$D:$D,$H$2+8)*1))
I10: =IF($H$2="",NA(),IF(INDEX(CSV!$A:$A,$H$2+9)="",NA(),INDEX(CSV!$A:$A,$H$2+9)*1)) | J10: =IF($H$2="",NA(),IF(INDEX(CSV!$B:$B,$H$2+9)="",NA(),INDEX(CSV!$B:$B,$H$2+9)*1)) | K10: =IF($H$2="",NA(),IF(INDEX(CSV!$D:$D,$H$2+9)="",NA(),INDEX(CSV!$D:$D,$H$2+9)*1))
A11: Tus resultados | I11: =IF($H$2="",NA(),IF(INDEX(CSV!$A:$A,$H$2+10)="",NA(),INDEX(CSV!$A:$A,$H$2+10)*1)) | J11: =IF($H$2="",NA(),IF(INDEX(CSV!$B:$B,$H$2+10)="",NA(),INDEX(CSV!$B:$B,$H$2+10)*1)) | K11: =IF($H$2="",NA(),IF(INDEX(CSV!$D:$D,$H$2+10)="",NA(),INDEX(CSV!$D:$D,$H$2+10)*1))
A12: ★ Resistencia del termistor a tu temperatura (Ω) | B12: =IFERROR(VLOOKUP("resultado:R_T",CSV!$A:$B,2,FALSE),"") | I12: =IF($H$2="",NA(),IF(INDEX(CSV!$A:$A,$H$2+11)="",NA(),INDEX(CSV!$A:$A,$H$2+11)*1)) | J12: =IF($H$2="",NA(),IF(INDEX(CSV!$B:$B,$H$2+11)="",NA(),INDEX(CSV!$B:$B,$H$2+11)*1)) | K12: =IF($H$2="",NA(),IF(INDEX(CSV!$D:$D,$H$2+11)="",NA(),INDEX(CSV!$D:$D,$H$2+11)*1))
A13: Voltaje del divisor (V) | B13: =IFERROR(VLOOKUP("resultado:V_T",CSV!$A:$B,2,FALSE),"") | I13: =IF($H$2="",NA(),IF(INDEX(CSV!$A:$A,$H$2+12)="",NA(),INDEX(CSV!$A:$A,$H$2+12)*1)) | J13: =IF($H$2="",NA(),IF(INDEX(CSV!$B:$B,$H$2+12)="",NA(),INDEX(CSV!$B:$B,$H$2+12)*1)) | K13: =IF($H$2="",NA(),IF(INDEX(CSV!$D:$D,$H$2+12)="",NA(),INDEX(CSV!$D:$D,$H$2+12)*1))
A14: Cuenta del convertidor | B14: =IFERROR(VLOOKUP("resultado:N_T",CSV!$A:$B,2,FALSE),"") | I14: =IF($H$2="",NA(),IF(INDEX(CSV!$A:$A,$H$2+13)="",NA(),INDEX(CSV!$A:$A,$H$2+13)*1)) | J14: =IF($H$2="",NA(),IF(INDEX(CSV!$B:$B,$H$2+13)="",NA(),INDEX(CSV!$B:$B,$H$2+13)*1)) | K14: =IF($H$2="",NA(),IF(INDEX(CSV!$D:$D,$H$2+13)="",NA(),INDEX(CSV!$D:$D,$H$2+13)*1))
A15: Datos por día con tu intervalo (kB) | B15: =IFERROR(VLOOKUP("resultado:kB_dia",CSV!$A:$B,2,FALSE),"") | I15: =IF($H$2="",NA(),IF(INDEX(CSV!$A:$A,$H$2+14)="",NA(),INDEX(CSV!$A:$A,$H$2+14)*1)) | J15: =IF($H$2="",NA(),IF(INDEX(CSV!$B:$B,$H$2+14)="",NA(),INDEX(CSV!$B:$B,$H$2+14)*1)) | K15: =IF($H$2="",NA(),IF(INDEX(CSV!$D:$D,$H$2+14)="",NA(),INDEX(CSV!$D:$D,$H$2+14)*1))
A16: Error máximo predicho al guardar cuentas (°C) | B16: =IFERROR(VLOOKUP("resultado:resol_pred_C",CSV!$A:$B,2,FALSE),"") | I16: =IF($H$2="",NA(),IF(INDEX(CSV!$A:$A,$H$2+15)="",NA(),INDEX(CSV!$A:$A,$H$2+15)*1)) | J16: =IF($H$2="",NA(),IF(INDEX(CSV!$B:$B,$H$2+15)="",NA(),INDEX(CSV!$B:$B,$H$2+15)*1)) | K16: =IF($H$2="",NA(),IF(INDEX(CSV!$D:$D,$H$2+15)="",NA(),INDEX(CSV!$D:$D,$H$2+15)*1))
A17: Error máximo obtenido en la semana (°C) | B17: =IFERROR(VLOOKUP("resultado:error_obt_C",CSV!$A:$B,2,FALSE),"") | I17: =IF($H$2="",NA(),IF(INDEX(CSV!$A:$A,$H$2+16)="",NA(),INDEX(CSV!$A:$A,$H$2+16)*1)) | J17: =IF($H$2="",NA(),IF(INDEX(CSV!$B:$B,$H$2+16)="",NA(),INDEX(CSV!$B:$B,$H$2+16)*1)) | K17: =IF($H$2="",NA(),IF(INDEX(CSV!$D:$D,$H$2+16)="",NA(),INDEX(CSV!$D:$D,$H$2+16)*1))
I18: =IF($H$2="",NA(),IF(INDEX(CSV!$A:$A,$H$2+17)="",NA(),INDEX(CSV!$A:$A,$H$2+17)*1)) | J18: =IF($H$2="",NA(),IF(INDEX(CSV!$B:$B,$H$2+17)="",NA(),INDEX(CSV!$B:$B,$H$2+17)*1)) | K18: =IF($H$2="",NA(),IF(INDEX(CSV!$D:$D,$H$2+17)="",NA(),INDEX(CSV!$D:$D,$H$2+17)*1))
A19: Predicho contra obtenido | I19: =IF($H$2="",NA(),IF(INDEX(CSV!$A:$A,$H$2+18)="",NA(),INDEX(CSV!$A:$A,$H$2+18)*1)) | J19: =IF($H$2="",NA(),IF(INDEX(CSV!$B:$B,$H$2+18)="",NA(),INDEX(CSV!$B:$B,$H$2+18)*1)) | K19: =IF($H$2="",NA(),IF(INDEX(CSV!$D:$D,$H$2+18)="",NA(),INDEX(CSV!$D:$D,$H$2+18)*1))
A20: Diferencia, obtenido contra predicho (%) | B20: =IF(OR(B16="",B17=""),"",(B17-B16)/B16*100) | I20: =IF($H$2="",NA(),IF(INDEX(CSV!$A:$A,$H$2+19)="",NA(),INDEX(CSV!$A:$A,$H$2+19)*1)) | J20: =IF($H$2="",NA(),IF(INDEX(CSV!$B:$B,$H$2+19)="",NA(),INDEX(CSV!$B:$B,$H$2+19)*1)) | K20: =IF($H$2="",NA(),IF(INDEX(CSV!$D:$D,$H$2+19)="",NA(),INDEX(CSV!$D:$D,$H$2+19)*1))
I21: =IF($H$2="",NA(),IF(INDEX(CSV!$A:$A,$H$2+20)="",NA(),INDEX(CSV!$A:$A,$H$2+20)*1)) | J21: =IF($H$2="",NA(),IF(INDEX(CSV!$B:$B,$H$2+20)="",NA(),INDEX(CSV!$B:$B,$H$2+20)*1)) | K21: =IF($H$2="",NA(),IF(INDEX(CSV!$D:$D,$H$2+20)="",NA(),INDEX(CSV!$D:$D,$H$2+20)*1))
A22: Preguntas del reporte ✎ | I22: =IF($H$2="",NA(),IF(INDEX(CSV!$A:$A,$H$2+21)="",NA(),INDEX(CSV!$A:$A,$H$2+21)*1)) | J22: =IF($H$2="",NA(),IF(INDEX(CSV!$B:$B,$H$2+21)="",NA(),INDEX(CSV!$B:$B,$H$2+21)*1)) | K22: =IF($H$2="",NA(),IF(INDEX(CSV!$D:$D,$H$2+21)="",NA(),INDEX(CSV!$D:$D,$H$2+21)*1))
A23: 1. Sigue un dato de tu semana por toda la cadena: temperatura, resistencia, voltaje, cuenta y temperatura reconstruida. Usa tus números. | I23: =IF($H$2="",NA(),IF(INDEX(CSV!$A:$A,$H$2+22)="",NA(),INDEX(CSV!$A:$A,$H$2+22)*1)) | J23: =IF($H$2="",NA(),IF(INDEX(CSV!$B:$B,$H$2+22)="",NA(),INDEX(CSV!$B:$B,$H$2+22)*1)) | K23: =IF($H$2="",NA(),IF(INDEX(CSV!$D:$D,$H$2+22)="",NA(),INDEX(CSV!$D:$D,$H$2+22)*1))
A24: 2. Si la planta registra 500 sensores con tu intervalo, ¿cuántos MB se acumulan en un año? ¿Qué harías con tantos datos? | I24: =IF($H$2="",NA(),IF(INDEX(CSV!$A:$A,$H$2+23)="",NA(),INDEX(CSV!$A:$A,$H$2+23)*1)) | J24: =IF($H$2="",NA(),IF(INDEX(CSV!$B:$B,$H$2+23)="",NA(),INDEX(CSV!$B:$B,$H$2+23)*1)) | K24: =IF($H$2="",NA(),IF(INDEX(CSV!$D:$D,$H$2+23)="",NA(),INDEX(CSV!$D:$D,$H$2+23)*1))
I25: =IF($H$2="",NA(),IF(INDEX(CSV!$A:$A,$H$2+24)="",NA(),INDEX(CSV!$A:$A,$H$2+24)*1)) | J25: =IF($H$2="",NA(),IF(INDEX(CSV!$B:$B,$H$2+24)="",NA(),INDEX(CSV!$B:$B,$H$2+24)*1)) | K25: =IF($H$2="",NA(),IF(INDEX(CSV!$D:$D,$H$2+24)="",NA(),INDEX(CSV!$D:$D,$H$2+24)*1))
A26: La gráfica se arma sola al importar tu CSV. Cambia su título por tu nombre (doble clic en el título); la leyenda ya lo toma de B1. | I26: =IF($H$2="",NA(),IF(INDEX(CSV!$A:$A,$H$2+25)="",NA(),INDEX(CSV!$A:$A,$H$2+25)*1)) | J26: =IF($H$2="",NA(),IF(INDEX(CSV!$B:$B,$H$2+25)="",NA(),INDEX(CSV!$B:$B,$H$2+25)*1)) | K26: =IF($H$2="",NA(),IF(INDEX(CSV!$D:$D,$H$2+25)="",NA(),INDEX(CSV!$D:$D,$H$2+25)*1))
I27: =IF($H$2="",NA(),IF(INDEX(CSV!$A:$A,$H$2+26)="",NA(),INDEX(CSV!$A:$A,$H$2+26)*1)) | J27: =IF($H$2="",NA(),IF(INDEX(CSV!$B:$B,$H$2+26)="",NA(),INDEX(CSV!$B:$B,$H$2+26)*1)) | K27: =IF($H$2="",NA(),IF(INDEX(CSV!$D:$D,$H$2+26)="",NA(),INDEX(CSV!$D:$D,$H$2+26)*1))
I28: =IF($H$2="",NA(),IF(INDEX(CSV!$A:$A,$H$2+27)="",NA(),INDEX(CSV!$A:$A,$H$2+27)*1)) | J28: =IF($H$2="",NA(),IF(INDEX(CSV!$B:$B,$H$2+27)="",NA(),INDEX(CSV!$B:$B,$H$2+27)*1)) | K28: =IF($H$2="",NA(),IF(INDEX(CSV!$D:$D,$H$2+27)="",NA(),INDEX(CSV!$D:$D,$H$2+27)*1))
I29: =IF($H$2="",NA(),IF(INDEX(CSV!$A:$A,$H$2+28)="",NA(),INDEX(CSV!$A:$A,$H$2+28)*1)) | J29: =IF($H$2="",NA(),IF(INDEX(CSV!$B:$B,$H$2+28)="",NA(),INDEX(CSV!$B:$B,$H$2+28)*1)) | K29: =IF($H$2="",NA(),IF(INDEX(CSV!$D:$D,$H$2+28)="",NA(),INDEX(CSV!$D:$D,$H$2+28)*1))
I30: =IF($H$2="",NA(),IF(INDEX(CSV!$A:$A,$H$2+29)="",NA(),INDEX(CSV!$A:$A,$H$2+29)*1)) | J30: =IF($H$2="",NA(),IF(INDEX(CSV!$B:$B,$H$2+29)="",NA(),INDEX(CSV!$B:$B,$H$2+29)*1)) | K30: =IF($H$2="",NA(),IF(INDEX(CSV!$D:$D,$H$2+29)="",NA(),INDEX(CSV!$D:$D,$H$2+29)*1))
I31: =IF($H$2="",NA(),IF(INDEX(CSV!$A:$A,$H$2+30)="",NA(),INDEX(CSV!$A:$A,$H$2+30)*1)) | J31: =IF($H$2="",NA(),IF(INDEX(CSV!$B:$B,$H$2+30)="",NA(),INDEX(CSV!$B:$B,$H$2+30)*1)) | K31: =IF($H$2="",NA(),IF(INDEX(CSV!$D:$D,$H$2+30)="",NA(),INDEX(CSV!$D:$D,$H$2+30)*1))
I32: =IF($H$2="",NA(),IF(INDEX(CSV!$A:$A,$H$2+31)="",NA(),INDEX(CSV!$A:$A,$H$2+31)*1)) | J32: =IF($H$2="",NA(),IF(INDEX(CSV!$B:$B,$H$2+31)="",NA(),INDEX(CSV!$B:$B,$H$2+31)*1)) | K32: =IF($H$2="",NA(),IF(INDEX(CSV!$D:$D,$H$2+31)="",NA(),INDEX(CSV!$D:$D,$H$2+31)*1))
I33: =IF($H$2="",NA(),IF(INDEX(CSV!$A:$A,$H$2+32)="",NA(),INDEX(CSV!$A:$A,$H$2+32)*1)) | J33: =IF($H$2="",NA(),IF(INDEX(CSV!$B:$B,$H$2+32)="",NA(),INDEX(CSV!$B:$B,$H$2+32)*1)) | K33: =IF($H$2="",NA(),IF(INDEX(CSV!$D:$D,$H$2+32)="",NA(),INDEX(CSV!$D:$D,$H$2+32)*1))
I34: =IF($H$2="",NA(),IF(INDEX(CSV!$A:$A,$H$2+33)="",NA(),INDEX(CSV!$A:$A,$H$2+33)*1)) | J34: =IF($H$2="",NA(),IF(INDEX(CSV!$B:$B,$H$2+33)="",NA(),INDEX(CSV!$B:$B,$H$2+33)*1)) | K34: =IF($H$2="",NA(),IF(INDEX(CSV!$D:$D,$H$2+33)="",NA(),INDEX(CSV!$D:$D,$H$2+33)*1))
I35: =IF($H$2="",NA(),IF(INDEX(CSV!$A:$A,$H$2+34)="",NA(),INDEX(CSV!$A:$A,$H$2+34)*1)) | J35: =IF($H$2="",NA(),IF(INDEX(CSV!$B:$B,$H$2+34)="",NA(),INDEX(CSV!$B:$B,$H$2+34)*1)) | K35: =IF($H$2="",NA(),IF(INDEX(CSV!$D:$D,$H$2+34)="",NA(),INDEX(CSV!$D:$D,$H$2+34)*1))
I36: =IF($H$2="",NA(),IF(INDEX(CSV!$A:$A,$H$2+35)="",NA(),INDEX(CSV!$A:$A,$H$2+35)*1)) | J36: =IF($H$2="",NA(),IF(INDEX(CSV!$B:$B,$H$2+35)="",NA(),INDEX(CSV!$B:$B,$H$2+35)*1)) | K36: =IF($H$2="",NA(),IF(INDEX(CSV!$D:$D,$H$2+35)="",NA(),INDEX(CSV!$D:$D,$H$2+35)*1))
I37: =IF($H$2="",NA(),IF(INDEX(CSV!$A:$A,$H$2+36)="",NA(),INDEX(CSV!$A:$A,$H$2+36)*1)) | J37: =IF($H$2="",NA(),IF(INDEX(CSV!$B:$B,$H$2+36)="",NA(),INDEX(CSV!$B:$B,$H$2+36)*1)) | K37: =IF($H$2="",NA(),IF(INDEX(CSV!$D:$D,$H$2+36)="",NA(),INDEX(CSV!$D:$D,$H$2+36)*1))
I38: =IF($H$2="",NA(),IF(INDEX(CSV!$A:$A,$H$2+37)="",NA(),INDEX(CSV!$A:$A,$H$2+37)*1)) | J38: =IF($H$2="",NA(),IF(INDEX(CSV!$B:$B,$H$2+37)="",NA(),INDEX(CSV!$B:$B,$H$2+37)*1)) | K38: =IF($H$2="",NA(),IF(INDEX(CSV!$D:$D,$H$2+37)="",NA(),INDEX(CSV!$D:$D,$H$2+37)*1))
I39: =IF($H$2="",NA(),IF(INDEX(CSV!$A:$A,$H$2+38)="",NA(),INDEX(CSV!$A:$A,$H$2+38)*1)) | J39: =IF($H$2="",NA(),IF(INDEX(CSV!$B:$B,$H$2+38)="",NA(),INDEX(CSV!$B:$B,$H$2+38)*1)) | K39: =IF($H$2="",NA(),IF(INDEX(CSV!$D:$D,$H$2+38)="",NA(),INDEX(CSV!$D:$D,$H$2+38)*1))
I40: =IF($H$2="",NA(),IF(INDEX(CSV!$A:$A,$H$2+39)="",NA(),INDEX(CSV!$A:$A,$H$2+39)*1)) | J40: =IF($H$2="",NA(),IF(INDEX(CSV!$B:$B,$H$2+39)="",NA(),INDEX(CSV!$B:$B,$H$2+39)*1)) | K40: =IF($H$2="",NA(),IF(INDEX(CSV!$D:$D,$H$2+39)="",NA(),INDEX(CSV!$D:$D,$H$2+39)*1))
...

Sheet CSV
A1: Importa aquí tu CSV: Archivo → Importar → Subir → Reemplazar la hoja actual
