Workbook

Sheet Resultados
A1: Nombre completo ✎ | H1: Encabezado en CSV | I1: Lectura (h) | J1: ="Real · "&$B$1 | K1: ="Registrada · "&$B$1
A2: Código de alumno ✎ | H2: =IFERROR(MATCH("fecha",CSV!$A:$A,0),"") | I2: =IF(ISNA(J2),NA(),0) | J2: =IF($H$2="",NA(),IFERROR(INDEX(CSV!$B:$B,$H$2+1)*1,NA())) | K2: =IF($H$2="",NA(),IFERROR(INDEX(CSV!$C:$C,$H$2+1)*1,NA()))
A3: Código en el CSV | B3: =IFERROR(VLOOKUP("codigo",CSV!$A:$B,2,FALSE),"") | I3: =IF(ISNA(J3),NA(),1) | J3: =IF($H$2="",NA(),IFERROR(INDEX(CSV!$B:$B,$H$2+2)*1,NA())) | K3: =IF($H$2="",NA(),IFERROR(INDEX(CSV!$C:$C,$H$2+2)*1,NA()))
A4: Verificación | B4: =IF(B3="","Importa tu CSV",IF(B2="","Escribe tu código",IF(TRIM(B3&"")=TRIM(B2&""),"OK","NO COINCIDE"))) | I4: =IF(ISNA(J4),NA(),2) | J4: =IF($H$2="",NA(),IFERROR(INDEX(CSV!$B:$B,$H$2+3)*1,NA())) | K4: =IF($H$2="",NA(),IFERROR(INDEX(CSV!$C:$C,$H$2+3)*1,NA()))
A5: Huella del cuaderno | B5: =IFERROR(VLOOKUP("huella",CSV!$A:$B,2,FALSE),"") | I5: =IF(ISNA(J5),NA(),3) | J5: =IF($H$2="",NA(),IFERROR(INDEX(CSV!$B:$B,$H$2+4)*1,NA())) | K5: =IF($H$2="",NA(),IFERROR(INDEX(CSV!$C:$C,$H$2+4)*1,NA()))
A6: Sesión | B6: =IFERROR(VLOOKUP("sesion",CSV!$A:$B,2,FALSE),"") | I6: =IF(ISNA(J6),NA(),4) | J6: =IF($H$2="",NA(),IFERROR(INDEX(CSV!$B:$B,$H$2+5)*1,NA())) | K6: =IF($H$2="",NA(),IFERROR(INDEX(CSV!$C:$C,$H$2+5)*1,NA()))
A7: Fuente de los datos | B7: =IFERROR(VLOOKUP("fuente",CSV!$A:$B,2,FALSE),"") | I7: =IF(ISNA(J7),NA(),5) | J7: =IF($H$2="",NA(),IFERROR(INDEX(CSV!$B:$B,$H$2+6)*1,NA())) | K7: =IF($H$2="",NA(),IFERROR(INDEX(CSV!$C:$C,$H$2+6)*1,NA()))
A8: Semana | B8: =IFERROR(VLOOKUP("semana",CSV!$A:$B,2,FALSE),"") | I8: =IF(ISNA(J8),NA(),6) | J8: =IF($H$2="",NA(),IFERROR(INDEX(CSV!$B:$B,$H$2+7)*1,NA())) | K8: =IF($H$2="",NA(),IFERROR(INDEX(CSV!$C:$C,$H$2+7)*1,NA()))
I9: =IF(ISNA(J9),NA(),7) | J9: =IF($H$2="",NA(),IFERROR(INDEX(CSV!$B:$B,$H$2+8)*1,NA())) | K9: =IF($H$2="",NA(),IFERROR(INDEX(CSV!$C:$C,$H$2+8)*1,NA()))
A10: Predicho contra obtenido | I10: =IF(ISNA(J10),NA(),8) | J10: =IF($H$2="",NA(),IFERROR(INDEX(CSV!$B:$B,$H$2+9)*1,NA())) | K10: =IF($H$2="",NA(),IFERROR(INDEX(CSV!$C:$C,$H$2+9)*1,NA()))
A11: LSB de tu convertidor (°C) | B11: =IFERROR(VLOOKUP("resultado:lsb_C",CSV!$A:$B,2,FALSE),"") | I11: =IF(ISNA(J11),NA(),9) | J11: =IF($H$2="",NA(),IFERROR(INDEX(CSV!$B:$B,$H$2+10)*1,NA())) | K11: =IF($H$2="",NA(),IFERROR(INDEX(CSV!$C:$C,$H$2+10)*1,NA()))
A12: Error máximo predicho, ejercicio 2 (°C) | B12: =IFERROR(VLOOKUP("resultado:error_predicho_C",CSV!$A:$B,2,FALSE),"") | I12: =IF(ISNA(J12),NA(),10) | J12: =IF($H$2="",NA(),IFERROR(INDEX(CSV!$B:$B,$H$2+11)*1,NA())) | K12: =IF($H$2="",NA(),IFERROR(INDEX(CSV!$C:$C,$H$2+11)*1,NA()))
A13: Error máximo obtenido con datos reales (°C) | B13: =IFERROR(VLOOKUP("resultado:error_obtenido_C",CSV!$A:$B,2,FALSE),"") | I13: =IF(ISNA(J13),NA(),11) | J13: =IF($H$2="",NA(),IFERROR(INDEX(CSV!$B:$B,$H$2+12)*1,NA())) | K13: =IF($H$2="",NA(),IFERROR(INDEX(CSV!$C:$C,$H$2+12)*1,NA()))
A14: Diferencia, obtenido contra predicho (%) | B14: =IF(OR(B12="",B13=""),"",(B13-B12)/B12*100) | I14: =IF(ISNA(J14),NA(),12) | J14: =IF($H$2="",NA(),IFERROR(INDEX(CSV!$B:$B,$H$2+13)*1,NA())) | K14: =IF($H$2="",NA(),IFERROR(INDEX(CSV!$C:$C,$H$2+13)*1,NA()))
A15: ¿El error obtenido queda dentro de lo predicho? | B15: =IF(B13="","",IF(B13<=B12,"Sí","No")) | I15: =IF(ISNA(J15),NA(),13) | J15: =IF($H$2="",NA(),IFERROR(INDEX(CSV!$B:$B,$H$2+14)*1,NA())) | K15: =IF($H$2="",NA(),IFERROR(INDEX(CSV!$C:$C,$H$2+14)*1,NA()))
I16: =IF(ISNA(J16),NA(),14) | J16: =IF($H$2="",NA(),IFERROR(INDEX(CSV!$B:$B,$H$2+15)*1,NA())) | K16: =IF($H$2="",NA(),IFERROR(INDEX(CSV!$C:$C,$H$2+15)*1,NA()))
A17: Preguntas del reporte ✎ | I17: =IF(ISNA(J17),NA(),15) | J17: =IF($H$2="",NA(),IFERROR(INDEX(CSV!$B:$B,$H$2+16)*1,NA())) | K17: =IF($H$2="",NA(),IFERROR(INDEX(CSV!$C:$C,$H$2+16)*1,NA()))
A18: 1. ¿Por qué el error obtenido no pasa de medio LSB? Usa tus números. | I18: =IF(ISNA(J18),NA(),16) | J18: =IF($H$2="",NA(),IFERROR(INDEX(CSV!$B:$B,$H$2+17)*1,NA())) | K18: =IF($H$2="",NA(),IFERROR(INDEX(CSV!$C:$C,$H$2+17)*1,NA()))
A19: 2. Para registrar la temperatura de un horno de reflujo (de 25 a 260 °C), ¿qué convertidor (bits) e intervalo elegirías y por qué? | I19: =IF(ISNA(J19),NA(),17) | J19: =IF($H$2="",NA(),IFERROR(INDEX(CSV!$B:$B,$H$2+18)*1,NA())) | K19: =IF($H$2="",NA(),IFERROR(INDEX(CSV!$C:$C,$H$2+18)*1,NA()))
I20: =IF(ISNA(J20),NA(),18) | J20: =IF($H$2="",NA(),IFERROR(INDEX(CSV!$B:$B,$H$2+19)*1,NA())) | K20: =IF($H$2="",NA(),IFERROR(INDEX(CSV!$C:$C,$H$2+19)*1,NA()))
A21: La gráfica se arma sola al importar tu CSV. Cambia su título por tu nombre (doble clic en el título); la leyenda ya lo toma de B1. | I21: =IF(ISNA(J21),NA(),19) | J21: =IF($H$2="",NA(),IFERROR(INDEX(CSV!$B:$B,$H$2+20)*1,NA())) | K21: =IF($H$2="",NA(),IFERROR(INDEX(CSV!$C:$C,$H$2+20)*1,NA()))
I22: =IF(ISNA(J22),NA(),20) | J22: =IF($H$2="",NA(),IFERROR(INDEX(CSV!$B:$B,$H$2+21)*1,NA())) | K22: =IF($H$2="",NA(),IFERROR(INDEX(CSV!$C:$C,$H$2+21)*1,NA()))
I23: =IF(ISNA(J23),NA(),21) | J23: =IF($H$2="",NA(),IFERROR(INDEX(CSV!$B:$B,$H$2+22)*1,NA())) | K23: =IF($H$2="",NA(),IFERROR(INDEX(CSV!$C:$C,$H$2+22)*1,NA()))
I24: =IF(ISNA(J24),NA(),22) | J24: =IF($H$2="",NA(),IFERROR(INDEX(CSV!$B:$B,$H$2+23)*1,NA())) | K24: =IF($H$2="",NA(),IFERROR(INDEX(CSV!$C:$C,$H$2+23)*1,NA()))
I25: =IF(ISNA(J25),NA(),23) | J25: =IF($H$2="",NA(),IFERROR(INDEX(CSV!$B:$B,$H$2+24)*1,NA())) | K25: =IF($H$2="",NA(),IFERROR(INDEX(CSV!$C:$C,$H$2+24)*1,NA()))
I26: =IF(ISNA(J26),NA(),24) | J26: =IF($H$2="",NA(),IFERROR(INDEX(CSV!$B:$B,$H$2+25)*1,NA())) | K26: =IF($H$2="",NA(),IFERROR(INDEX(CSV!$C:$C,$H$2+25)*1,NA()))
I27: =IF(ISNA(J27),NA(),25) | J27: =IF($H$2="",NA(),IFERROR(INDEX(CSV!$B:$B,$H$2+26)*1,NA())) | K27: =IF($H$2="",NA(),IFERROR(INDEX(CSV!$C:$C,$H$2+26)*1,NA()))
I28: =IF(ISNA(J28),NA(),26) | J28: =IF($H$2="",NA(),IFERROR(INDEX(CSV!$B:$B,$H$2+27)*1,NA())) | K28: =IF($H$2="",NA(),IFERROR(INDEX(CSV!$C:$C,$H$2+27)*1,NA()))
I29: =IF(ISNA(J29),NA(),27) | J29: =IF($H$2="",NA(),IFERROR(INDEX(CSV!$B:$B,$H$2+28)*1,NA())) | K29: =IF($H$2="",NA(),IFERROR(INDEX(CSV!$C:$C,$H$2+28)*1,NA()))
I30: =IF(ISNA(J30),NA(),28) | J30: =IF($H$2="",NA(),IFERROR(INDEX(CSV!$B:$B,$H$2+29)*1,NA())) | K30: =IF($H$2="",NA(),IFERROR(INDEX(CSV!$C:$C,$H$2+29)*1,NA()))
I31: =IF(ISNA(J31),NA(),29) | J31: =IF($H$2="",NA(),IFERROR(INDEX(CSV!$B:$B,$H$2+30)*1,NA())) | K31: =IF($H$2="",NA(),IFERROR(INDEX(CSV!$C:$C,$H$2+30)*1,NA()))
I32: =IF(ISNA(J32),NA(),30) | J32: =IF($H$2="",NA(),IFERROR(INDEX(CSV!$B:$B,$H$2+31)*1,NA())) | K32: =IF($H$2="",NA(),IFERROR(INDEX(CSV!$C:$C,$H$2+31)*1,NA()))
I33: =IF(ISNA(J33),NA(),31) | J33: =IF($H$2="",NA(),IFERROR(INDEX(CSV!$B:$B,$H$2+32)*1,NA())) | K33: =IF($H$2="",NA(),IFERROR(INDEX(CSV!$C:$C,$H$2+32)*1,NA()))
I34: =IF(ISNA(J34),NA(),32) | J34: =IF($H$2="",NA(),IFERROR(INDEX(CSV!$B:$B,$H$2+33)*1,NA())) | K34: =IF($H$2="",NA(),IFERROR(INDEX(CSV!$C:$C,$H$2+33)*1,NA()))
I35: =IF(ISNA(J35),NA(),33) | J35: =IF($H$2="",NA(),IFERROR(INDEX(CSV!$B:$B,$H$2+34)*1,NA())) | K35: =IF($H$2="",NA(),IFERROR(INDEX(CSV!$C:$C,$H$2+34)*1,NA()))
I36: =IF(ISNA(J36),NA(),34) | J36: =IF($H$2="",NA(),IFERROR(INDEX(CSV!$B:$B,$H$2+35)*1,NA())) | K36: =IF($H$2="",NA(),IFERROR(INDEX(CSV!$C:$C,$H$2+35)*1,NA()))
I37: =IF(ISNA(J37),NA(),35) | J37: =IF($H$2="",NA(),IFERROR(INDEX(CSV!$B:$B,$H$2+36)*1,NA())) | K37: =IF($H$2="",NA(),IFERROR(INDEX(CSV!$C:$C,$H$2+36)*1,NA()))
I38: =IF(ISNA(J38),NA(),36) | J38: =IF($H$2="",NA(),IFERROR(INDEX(CSV!$B:$B,$H$2+37)*1,NA())) | K38: =IF($H$2="",NA(),IFERROR(INDEX(CSV!$C:$C,$H$2+37)*1,NA()))
I39: =IF(ISNA(J39),NA(),37) | J39: =IF($H$2="",NA(),IFERROR(INDEX(CSV!$B:$B,$H$2+38)*1,NA())) | K39: =IF($H$2="",NA(),IFERROR(INDEX(CSV!$C:$C,$H$2+38)*1,NA()))
I40: =IF(ISNA(J40),NA(),38) | J40: =IF($H$2="",NA(),IFERROR(INDEX(CSV!$B:$B,$H$2+39)*1,NA())) | K40: =IF($H$2="",NA(),IFERROR(INDEX(CSV!$C:$C,$H$2+39)*1,NA()))
...

Sheet CSV
A1: Importa aquí tu CSV: Archivo → Importar → Subir → Reemplazar la hoja actual
